[2025-09-11 10:30:47,906] {taskinstance.py:1159} INFO - Dependencies all met for <TaskInstance: Daily_img_transfer.move_images manual__2025-09-11T10:30:45.804439+00:00 [queued]>
[2025-09-11 10:30:47,913] {taskinstance.py:1159} INFO - Dependencies all met for <TaskInstance: Daily_img_transfer.move_images manual__2025-09-11T10:30:45.804439+00:00 [queued]>
[2025-09-11 10:30:47,914] {taskinstance.py:1356} INFO - 
--------------------------------------------------------------------------------
[2025-09-11 10:30:47,916] {taskinstance.py:1357} INFO - Starting attempt 1 of 1
[2025-09-11 10:30:47,916] {taskinstance.py:1358} INFO - 
--------------------------------------------------------------------------------
[2025-09-11 10:30:47,926] {taskinstance.py:1377} INFO - Executing <Task(BashOperator): move_images> on 2025-09-11 10:30:45.804439+00:00
[2025-09-11 10:30:47,930] {standard_task_runner.py:52} INFO - Started process 2206 to run task
[2025-09-11 10:30:47,931] {standard_task_runner.py:79} INFO - Running: ['***', 'tasks', 'run', 'Daily_img_transfer', 'move_images', 'manual__2025-09-11T10:30:45.804439+00:00', '--job-id', '43', '--raw', '--subdir', 'DAGS_FOLDER/dags.py', '--cfg-path', '/tmp/tmpvo7j9ydu', '--error-file', '/tmp/tmp3ki52dls']
[2025-09-11 10:30:47,932] {standard_task_runner.py:80} INFO - Job 43: Subtask move_images
[2025-09-11 10:30:47,969] {task_command.py:370} INFO - Running <TaskInstance: Daily_img_transfer.move_images manual__2025-09-11T10:30:45.804439+00:00 [running]> on host 225d5ec060dd
[2025-09-11 10:30:48,016] {taskinstance.py:1571} INFO - Exporting the following env vars:
AIRFLOW_CTX_DAG_OWNER=***
AIRFLOW_CTX_DAG_ID=Daily_img_transfer
AIRFLOW_CTX_TASK_ID=move_images
AIRFLOW_CTX_EXECUTION_DATE=2025-09-11T10:30:45.804439+00:00
AIRFLOW_CTX_TRY_NUMBER=1
AIRFLOW_CTX_DAG_RUN_ID=manual__2025-09-11T10:30:45.804439+00:00
[2025-09-11 10:30:48,024] {taskinstance.py:1889} ERROR - Task failed with exception
Traceback (most recent call last):
  File "/home/airflow/.local/lib/python3.7/site-packages/airflow/operators/bash.py", line 181, in execute
    raise AirflowException(f"Can not find the cwd: {self.cwd}")
airflow.exceptions.AirflowException: Can not find the cwd: C:\Users\maria\Desktop\dsl_ft_33\00_Projets_certif\bloc4\03_Jedha_aia_bloc_4_Final_project\wakee_lead
[2025-09-11 10:30:48,026] {taskinstance.py:1400} INFO - Marking task as FAILED. dag_id=Daily_img_transfer, task_id=move_images, execution_date=20250911T103045, start_date=20250911T103047, end_date=20250911T103048
[2025-09-11 10:30:48,034] {standard_task_runner.py:97} ERROR - Failed to execute job 43 for task move_images (Can not find the cwd: C:\Users\maria\Desktop\dsl_ft_33\00_Projets_certif\bloc4\03_Jedha_aia_bloc_4_Final_project\wakee_lead; 2206)
[2025-09-11 10:30:48,065] {local_task_job.py:156} INFO - Task exited with return code 1
[2025-09-11 10:30:48,086] {local_task_job.py:273} INFO - 0 downstream tasks scheduled from follow-on schedule check
