[2025-09-10 16:27:40,417] {taskinstance.py:1159} INFO - Dependencies all met for <TaskInstance: Daily_img_transfer.move_images manual__2025-09-10T16:27:38.710364+00:00 [queued]>
[2025-09-10 16:27:40,424] {taskinstance.py:1159} INFO - Dependencies all met for <TaskInstance: Daily_img_transfer.move_images manual__2025-09-10T16:27:38.710364+00:00 [queued]>
[2025-09-10 16:27:40,425] {taskinstance.py:1356} INFO - 
--------------------------------------------------------------------------------
[2025-09-10 16:27:40,426] {taskinstance.py:1357} INFO - Starting attempt 1 of 1
[2025-09-10 16:27:40,426] {taskinstance.py:1358} INFO - 
--------------------------------------------------------------------------------
[2025-09-10 16:27:40,437] {taskinstance.py:1377} INFO - Executing <Task(BashOperator): move_images> on 2025-09-10 16:27:38.710364+00:00
[2025-09-10 16:27:40,441] {standard_task_runner.py:52} INFO - Started process 1308 to run task
[2025-09-10 16:27:40,443] {standard_task_runner.py:79} INFO - Running: ['***', 'tasks', 'run', 'Daily_img_transfer', 'move_images', 'manual__2025-09-10T16:27:38.710364+00:00', '--job-id', '15', '--raw', '--subdir', 'DAGS_FOLDER/dags.py', '--cfg-path', '/tmp/tmp_vf17mlu', '--error-file', '/tmp/tmp6dfultxo']
[2025-09-10 16:27:40,443] {standard_task_runner.py:80} INFO - Job 15: Subtask move_images
[2025-09-10 16:27:40,482] {task_command.py:370} INFO - Running <TaskInstance: Daily_img_transfer.move_images manual__2025-09-10T16:27:38.710364+00:00 [running]> on host 17d4e251db5b
[2025-09-10 16:27:41,682] {taskinstance.py:1571} INFO - Exporting the following env vars:
AIRFLOW_CTX_DAG_OWNER=***
AIRFLOW_CTX_DAG_ID=Daily_img_transfer
AIRFLOW_CTX_TASK_ID=move_images
AIRFLOW_CTX_EXECUTION_DATE=2025-09-10T16:27:38.710364+00:00
AIRFLOW_CTX_TRY_NUMBER=1
AIRFLOW_CTX_DAG_RUN_ID=manual__2025-09-10T16:27:38.710364+00:00
[2025-09-10 16:27:41,683] {subprocess.py:62} INFO - Tmp dir root location: 
 /tmp
[2025-09-10 16:27:41,684] {subprocess.py:74} INFO - Running command: ['bash', '-c', 'move.sh ']
[2025-09-10 16:27:41,691] {subprocess.py:85} INFO - Output:
[2025-09-10 16:27:41,692] {subprocess.py:92} INFO - bash: line 1: move.sh: command not found
[2025-09-10 16:27:41,692] {subprocess.py:96} INFO - Command exited with return code 127
[2025-09-10 16:27:41,703] {taskinstance.py:1889} ERROR - Task failed with exception
Traceback (most recent call last):
  File "/home/airflow/.local/lib/python3.7/site-packages/airflow/operators/bash.py", line 195, in execute
    f'Bash command failed. The command returned a non-zero exit code {result.exit_code}.'
airflow.exceptions.AirflowException: Bash command failed. The command returned a non-zero exit code 127.
[2025-09-10 16:27:41,706] {taskinstance.py:1400} INFO - Marking task as FAILED. dag_id=Daily_img_transfer, task_id=move_images, execution_date=20250910T162738, start_date=20250910T162740, end_date=20250910T162741
[2025-09-10 16:27:41,715] {standard_task_runner.py:97} ERROR - Failed to execute job 15 for task move_images (Bash command failed. The command returned a non-zero exit code 127.; 1308)
[2025-09-10 16:27:43,637] {local_task_job.py:156} INFO - Task exited with return code 1
[2025-09-10 16:27:43,664] {local_task_job.py:273} INFO - 0 downstream tasks scheduled from follow-on schedule check
