[2025-09-11 10:38:38,048] {taskinstance.py:1159} INFO - Dependencies all met for <TaskInstance: Daily_img_transfer.move_images manual__2025-09-11T10:38:36.298085+00:00 [queued]>
[2025-09-11 10:38:38,056] {taskinstance.py:1159} INFO - Dependencies all met for <TaskInstance: Daily_img_transfer.move_images manual__2025-09-11T10:38:36.298085+00:00 [queued]>
[2025-09-11 10:38:38,057] {taskinstance.py:1356} INFO - 
--------------------------------------------------------------------------------
[2025-09-11 10:38:38,057] {taskinstance.py:1357} INFO - Starting attempt 1 of 1
[2025-09-11 10:38:38,058] {taskinstance.py:1358} INFO - 
--------------------------------------------------------------------------------
[2025-09-11 10:38:38,068] {taskinstance.py:1377} INFO - Executing <Task(BashOperator): move_images> on 2025-09-11 10:38:36.298085+00:00
[2025-09-11 10:38:38,072] {standard_task_runner.py:52} INFO - Started process 2567 to run task
[2025-09-11 10:38:38,074] {standard_task_runner.py:79} INFO - Running: ['***', 'tasks', 'run', 'Daily_img_transfer', 'move_images', 'manual__2025-09-11T10:38:36.298085+00:00', '--job-id', '47', '--raw', '--subdir', 'DAGS_FOLDER/dags.py', '--cfg-path', '/tmp/tmptrw3y8j3', '--error-file', '/tmp/tmplubi17ss']
[2025-09-11 10:38:38,074] {standard_task_runner.py:80} INFO - Job 47: Subtask move_images
[2025-09-11 10:38:38,113] {task_command.py:370} INFO - Running <TaskInstance: Daily_img_transfer.move_images manual__2025-09-11T10:38:36.298085+00:00 [running]> on host 225d5ec060dd
[2025-09-11 10:38:38,160] {taskinstance.py:1571} INFO - Exporting the following env vars:
AIRFLOW_CTX_DAG_OWNER=***
AIRFLOW_CTX_DAG_ID=Daily_img_transfer
AIRFLOW_CTX_TASK_ID=move_images
AIRFLOW_CTX_EXECUTION_DATE=2025-09-11T10:38:36.298085+00:00
AIRFLOW_CTX_TRY_NUMBER=1
AIRFLOW_CTX_DAG_RUN_ID=manual__2025-09-11T10:38:36.298085+00:00
[2025-09-11 10:38:38,169] {taskinstance.py:1889} ERROR - Task failed with exception
Traceback (most recent call last):
  File "/home/airflow/.local/lib/python3.7/site-packages/airflow/operators/bash.py", line 181, in execute
    raise AirflowException(f"Can not find the cwd: {self.cwd}")
airflow.exceptions.AirflowException: Can not find the cwd: C:\Users\maria\Desktop\dsl_ft_33\00_Projets_certif\bloc4\03_Jedha_aia_bloc_4_Final_project\wakee_lead\
[2025-09-11 10:38:38,171] {taskinstance.py:1400} INFO - Marking task as FAILED. dag_id=Daily_img_transfer, task_id=move_images, execution_date=20250911T103836, start_date=20250911T103838, end_date=20250911T103838
[2025-09-11 10:38:38,179] {standard_task_runner.py:97} ERROR - Failed to execute job 47 for task move_images (Can not find the cwd: C:\Users\maria\Desktop\dsl_ft_33\00_Projets_certif\bloc4\03_Jedha_aia_bloc_4_Final_project\wakee_lead\; 2567)
[2025-09-11 10:38:38,206] {local_task_job.py:156} INFO - Task exited with return code 1
[2025-09-11 10:38:38,235] {local_task_job.py:273} INFO - 0 downstream tasks scheduled from follow-on schedule check
