[2025-09-11 09:19:23,694] {taskinstance.py:1159} INFO - Dependencies all met for <TaskInstance: Daily_img_transfer.change_directory manual__2025-09-11T09:19:22.317461+00:00 [queued]>
[2025-09-11 09:19:23,701] {taskinstance.py:1159} INFO - Dependencies all met for <TaskInstance: Daily_img_transfer.change_directory manual__2025-09-11T09:19:22.317461+00:00 [queued]>
[2025-09-11 09:19:23,701] {taskinstance.py:1356} INFO - 
--------------------------------------------------------------------------------
[2025-09-11 09:19:23,702] {taskinstance.py:1357} INFO - Starting attempt 1 of 1
[2025-09-11 09:19:23,702] {taskinstance.py:1358} INFO - 
--------------------------------------------------------------------------------
[2025-09-11 09:19:23,713] {taskinstance.py:1377} INFO - Executing <Task(PythonOperator): change_directory> on 2025-09-11 09:19:22.317461+00:00
[2025-09-11 09:19:23,717] {standard_task_runner.py:52} INFO - Started process 2067 to run task
[2025-09-11 09:19:23,719] {standard_task_runner.py:79} INFO - Running: ['***', 'tasks', 'run', 'Daily_img_transfer', 'change_directory', 'manual__2025-09-11T09:19:22.317461+00:00', '--job-id', '29', '--raw', '--subdir', 'DAGS_FOLDER/dags.py', '--cfg-path', '/tmp/tmpe6ui4qpi', '--error-file', '/tmp/tmpgo9bzhiv']
[2025-09-11 09:19:23,719] {standard_task_runner.py:80} INFO - Job 29: Subtask change_directory
[2025-09-11 09:19:23,757] {task_command.py:370} INFO - Running <TaskInstance: Daily_img_transfer.change_directory manual__2025-09-11T09:19:22.317461+00:00 [running]> on host 17d4e251db5b
[2025-09-11 09:19:23,802] {taskinstance.py:1571} INFO - Exporting the following env vars:
AIRFLOW_CTX_DAG_OWNER=***
AIRFLOW_CTX_DAG_ID=Daily_img_transfer
AIRFLOW_CTX_TASK_ID=change_directory
AIRFLOW_CTX_EXECUTION_DATE=2025-09-11T09:19:22.317461+00:00
AIRFLOW_CTX_TRY_NUMBER=1
AIRFLOW_CTX_DAG_RUN_ID=manual__2025-09-11T09:19:22.317461+00:00
[2025-09-11 09:19:23,803] {taskinstance.py:1889} ERROR - Task failed with exception
Traceback (most recent call last):
  File "/home/airflow/.local/lib/python3.7/site-packages/airflow/operators/python.py", line 171, in execute
    return_value = self.execute_callable()
  File "/home/airflow/.local/lib/python3.7/site-packages/airflow/operators/python.py", line 189, in execute_callable
    return self.python_callable(*self.op_args, **self.op_kwargs)
  File "/opt/airflow/dags/dags.py", line 15, in _change_directory
    os.chdir(r"C:\Users\maria\Desktop\dsl_ft_33\00_Projets_certif\bloc4\03_Jedha_aia_bloc_4_Final_project\wakee_lead")
FileNotFoundError: [Errno 2] No such file or directory: 'C:\\Users\\maria\\Desktop\\dsl_ft_33\\00_Projets_certif\\bloc4\\03_Jedha_aia_bloc_4_Final_project\\wakee_lead'
[2025-09-11 09:19:23,811] {taskinstance.py:1400} INFO - Marking task as FAILED. dag_id=Daily_img_transfer, task_id=change_directory, execution_date=20250911T091922, start_date=20250911T091923, end_date=20250911T091923
[2025-09-11 09:19:23,818] {standard_task_runner.py:97} ERROR - Failed to execute job 29 for task change_directory ([Errno 2] No such file or directory: 'C:\\Users\\maria\\Desktop\\dsl_ft_33\\00_Projets_certif\\bloc4\\03_Jedha_aia_bloc_4_Final_project\\wakee_lead'; 2067)
[2025-09-11 09:19:23,851] {local_task_job.py:156} INFO - Task exited with return code 1
[2025-09-11 09:19:23,879] {local_task_job.py:273} INFO - 0 downstream tasks scheduled from follow-on schedule check
