[2025-09-11 10:28:36,797] {taskinstance.py:1159} INFO - Dependencies all met for <TaskInstance: Daily_img_transfer.move_images manual__2025-09-11T10:28:35.763446+00:00 [queued]>
[2025-09-11 10:28:36,805] {taskinstance.py:1159} INFO - Dependencies all met for <TaskInstance: Daily_img_transfer.move_images manual__2025-09-11T10:28:35.763446+00:00 [queued]>
[2025-09-11 10:28:36,805] {taskinstance.py:1356} INFO - 
--------------------------------------------------------------------------------
[2025-09-11 10:28:36,806] {taskinstance.py:1357} INFO - Starting attempt 1 of 1
[2025-09-11 10:28:36,808] {taskinstance.py:1358} INFO - 
--------------------------------------------------------------------------------
[2025-09-11 10:28:36,819] {taskinstance.py:1377} INFO - Executing <Task(BashOperator): move_images> on 2025-09-11 10:28:35.763446+00:00
[2025-09-11 10:28:36,822] {standard_task_runner.py:52} INFO - Started process 2102 to run task
[2025-09-11 10:28:36,824] {standard_task_runner.py:79} INFO - Running: ['***', 'tasks', 'run', 'Daily_img_transfer', 'move_images', 'manual__2025-09-11T10:28:35.763446+00:00', '--job-id', '41', '--raw', '--subdir', 'DAGS_FOLDER/dags.py', '--cfg-path', '/tmp/tmpcqdsqx74', '--error-file', '/tmp/tmpq4f9wiu6']
[2025-09-11 10:28:36,825] {standard_task_runner.py:80} INFO - Job 41: Subtask move_images
[2025-09-11 10:28:36,863] {task_command.py:370} INFO - Running <TaskInstance: Daily_img_transfer.move_images manual__2025-09-11T10:28:35.763446+00:00 [running]> on host 225d5ec060dd
[2025-09-11 10:28:36,908] {taskinstance.py:1571} INFO - Exporting the following env vars:
AIRFLOW_CTX_DAG_OWNER=***
AIRFLOW_CTX_DAG_ID=Daily_img_transfer
AIRFLOW_CTX_TASK_ID=move_images
AIRFLOW_CTX_EXECUTION_DATE=2025-09-11T10:28:35.763446+00:00
AIRFLOW_CTX_TRY_NUMBER=1
AIRFLOW_CTX_DAG_RUN_ID=manual__2025-09-11T10:28:35.763446+00:00
[2025-09-11 10:28:36,916] {taskinstance.py:1889} ERROR - Task failed with exception
Traceback (most recent call last):
  File "/home/airflow/.local/lib/python3.7/site-packages/airflow/operators/bash.py", line 181, in execute
    raise AirflowException(f"Can not find the cwd: {self.cwd}")
airflow.exceptions.AirflowException: Can not find the cwd: C:/Users/maria/Desktop/dsl_ft_33/00_Projets_certif/bloc4/03_Jedha_aia_bloc_4_Final_project/wakee_lead
[2025-09-11 10:28:36,918] {taskinstance.py:1400} INFO - Marking task as FAILED. dag_id=Daily_img_transfer, task_id=move_images, execution_date=20250911T102835, start_date=20250911T102836, end_date=20250911T102836
[2025-09-11 10:28:36,925] {standard_task_runner.py:97} ERROR - Failed to execute job 41 for task move_images (Can not find the cwd: C:/Users/maria/Desktop/dsl_ft_33/00_Projets_certif/bloc4/03_Jedha_aia_bloc_4_Final_project/wakee_lead; 2102)
[2025-09-11 10:28:36,957] {local_task_job.py:156} INFO - Task exited with return code 1
[2025-09-11 10:28:36,984] {local_task_job.py:273} INFO - 0 downstream tasks scheduled from follow-on schedule check
